<?xml version="1.0"?>
<robot xmlns:xacro="http://www.ros.org/wiki/xacro">

    <xacro:macro  name="deepmind_bot_arm" params="parent origin_xyz yaw_angle robot_name">

      <link name="${robot_name}_arm1">
        <visual>
          <geometry>
              <mesh filename="package://deepmind_bot_description/meshes/arm1.dae" scale="${base_box_factor} ${base_box_factor} ${base_box_factor}"/>
          </geometry>
        </visual>

        <!-- <collision>
          <origin rpy="0 0 0" xyz="0 0 0"/>
          <geometry>
              <mesh filename="package://deepmind_bot_description/meshes/arm1.dae" scale="${base_box_factor} ${base_box_factor} ${base_box_factor}"/>
          </geometry>
        </collision> -->

        <inertial>
          <mass value="0.03"/>
          <origin rpy="0 0 0" xyz="-0.071 0 0.1"/>
          <inertia ixx="0.000183229375" ixy="0" ixz="0" iyy="0.000183229375" iyz="0" izz="0.00006633375"/>
        </inertial>

      </link>

        <joint name="${robot_name}_arm1_joint" type="revolute">
            <safety_controller k_position="1000.0" k_velocity="400.0" soft_lower_limit="-2.8973" soft_upper_limit="2.8973" />
            <origin rpy="0 0 ${yaw_angle}" xyz="${origin_xyz}" />
            <parent link="${parent}" />
            <child link="${robot_name}_arm1" />
            <axis xyz="1 0 0" />
            <limit effort="${arm_effort}" lower="-2.9671" upper="2.9671" velocity="2.3925" />
        </joint>


        <link name="${robot_name}_arm2">
        <visual>
          <geometry>
              <mesh filename="package://deepmind_bot_description/meshes/arm2.dae" scale="${base_box_factor} ${base_box_factor} ${base_box_factor}"/>
          </geometry>
        </visual>

        <!-- <collision>
          <origin rpy="0 0 0" xyz="0 0 0"/>
          <geometry>
              <mesh filename="package://deepmind_bot_description/meshes/arm2.dae" scale="${base_box_factor} ${base_box_factor} ${base_box_factor}"/>
          </geometry>
        </collision> -->

        <inertial>
          <mass value="0.03"/>
          <origin rpy="0 0 0" xyz="0 0 0.1535"/>
          <inertia ixx="0.000268789375" ixy="0" ixz="0" iyy="0.000268789375" iyz="0" izz="0.00006633375"/>
        </inertial>

      </link>

        <joint name="${robot_name}_arm2_joint" type="revolute">
            <safety_controller k_position="1000.0" k_velocity="400.0" soft_lower_limit="-2.8973" soft_upper_limit="2.8973" />
            <origin rpy="0 0 0" xyz="-0.07135 0 0.18406" />
            <parent link="${robot_name}_arm1" />
            <child link="${robot_name}_arm2" />
            <axis xyz="0 0 1" />
            <limit effort="${arm_effort}" lower="-2.9671" upper="2.9671" velocity="2.3925" />
        </joint>


        <link name="${robot_name}_arm3">
        <visual>
          <geometry>
              <mesh filename="package://deepmind_bot_description/meshes/arm3.dae" scale="${base_box_factor} ${base_box_factor} ${base_box_factor}"/>
          </geometry>
        </visual>

        <!-- <collision>
          <origin rpy="0 0 0" xyz="0 0 0"/>
          <geometry>
              <mesh filename="package://deepmind_bot_description/meshes/arm3.dae" scale="${base_box_factor} ${base_box_factor} ${base_box_factor}"/>
          </geometry>
        </collision> -->

        <inertial>
          <mass value="0.02"/>
          <origin rpy="0 0 0" xyz="-0.06 0 0"/>
          <inertia ixx="0.00006" ixy="0" ixz="0" iyy="0.00006" iyz="0" izz="0.00004096"/>
        </inertial>

      </link>

        <joint name="${robot_name}_arm3_joint" type="revolute">
            <safety_controller k_position="1000.0" k_velocity="400.0" soft_lower_limit="-2.8973" soft_upper_limit="2.8973" />
            <origin rpy="0 0 0" xyz="-0.07135 0 0.2454" />
            <parent link="${robot_name}_arm2" />
            <child link="${robot_name}_arm3" />
            <axis xyz="1 0 0" />
            <limit effort="${arm_effort}" lower="-2.9671" upper="2.9671" velocity="2.3925" />
        </joint>


        <link name="${robot_name}_arm4">
        <visual>
          <geometry>
              <mesh filename="package://deepmind_bot_description/meshes/arm4.dae" scale="${base_box_factor} ${base_box_factor} ${base_box_factor}"/>
          </geometry>
        </visual>

        <!-- <collision>
          <origin rpy="0 0 0" xyz="0 0 0"/>
          <geometry>
              <mesh filename="package://deepmind_bot_description/meshes/arm4.dae" scale="${base_box_factor} ${base_box_factor} ${base_box_factor}"/>
          </geometry>
        </collision> -->

        <inertial>
          <mass value="0.02"/>
          <origin rpy="0 0 0" xyz="0 0 0.191"/>
          <inertia ixx="0.00025571" ixy="0" ixz="0" iyy="0.00025571" iyz="0" izz="0.000025"/>
        </inertial>

      </link>

        <joint name="${robot_name}_arm4_joint" type="revolute">
            <safety_controller k_position="1000.0" k_velocity="400.0" soft_lower_limit="-2.8973" soft_upper_limit="2.8973" />
            <origin rpy="0 0 0" xyz="-0.066584 0 0.093033" />
            <parent link="${robot_name}_arm3" />
            <child link="${robot_name}_arm4" />
            <axis xyz="0 0 1" />
            <limit effort="${arm_effort}" lower="-2.9671" upper="2.9671" velocity="2.3925" />
        </joint>


        <link name="${robot_name}_arm5">
        <visual>
          <geometry>
              <mesh filename="package://deepmind_bot_description/meshes/arm5.dae" scale="${base_box_factor} ${base_box_factor} ${base_box_factor}"/>
          </geometry>
        </visual>

        <!-- <collision>
          <origin rpy="0 0 0" xyz="0 0 0"/>
          <geometry>
              <mesh filename="package://deepmind_bot_description/meshes/arm5.dae" scale="${base_box_factor} ${base_box_factor} ${base_box_factor}"/>
          </geometry>
        </collision> -->

        <inertial>
          <mass value="0.01"/>
          <origin rpy="0 0 0" xyz="0 0.03 -0.0705"/>
          <inertia ixx="0.000024548125" ixy="0" ixz="0" iyy="0.000024548125" iyz="0" izz="0.000016"/>
        </inertial>

      </link>

        <joint name="${robot_name}_arm5_joint" type="revolute">
            <safety_controller k_position="1000.0" k_velocity="400.0" soft_lower_limit="-2.8973" soft_upper_limit="2.8973" />
            <origin rpy="0 3.1416 3.1416" xyz="0 0.0495 0.33512" />
            <parent link="${robot_name}_arm4" />
            <child link="${robot_name}_arm5" />
            <axis xyz="0 1 0" />
            <limit effort="${arm_effort}" lower="-2.9671" upper="2.9671" velocity="2.3925" />
        </joint>


        <link name="${robot_name}_arm6">
        <visual>
          <geometry>
              <mesh filename="package://deepmind_bot_description/meshes/arm6.dae" scale="${base_box_factor} ${base_box_factor} ${base_box_factor}"/>
          </geometry>
        </visual>

        <!-- <collision>
          <origin rpy="0 0 0" xyz="0 0 0"/>
          <geometry>
              <mesh filename="package://deepmind_bot_description/meshes/arm6.dae" scale="${base_box_factor} ${base_box_factor} ${base_box_factor}"/>
          </geometry>
        </collision> -->

        <inertial>
          <mass value="0.01"/>
          <origin rpy="0 0 0" xyz="0 0 -0.03"/>
          <inertia ixx="0.000010980625" ixy="0" ixz="0" iyy="0.000010980625" iyz="0" izz="0.00001596125"/>
        </inertial>

      </link>

        <joint name="${robot_name}_arm6_joint" type="revolute">
            <safety_controller k_position="1000.0" k_velocity="400.0" soft_lower_limit="-2.8973" soft_upper_limit="2.8973" />
            <origin rpy="0 0 0" xyz="0 0.030218 -0.098925" />
            <parent link="${robot_name}_arm5" />
            <child link="${robot_name}_arm6" />
            <axis xyz="0 0 1" />
            <limit effort="${arm_effort}" lower="-2.9671" upper="2.9671" velocity="2.3925" />
        </joint>


        <!-- Gripper -->

        <link name="${robot_name}_gripper1">
        <visual>
          <geometry>
              <mesh filename="package://deepmind_bot_description/meshes/gripper.dae" scale="${base_box_factor} ${base_box_factor} ${base_box_factor}"/>
          </geometry>
        </visual>

        <!-- <collision>
          <origin rpy="0 0 0" xyz="0 0 0"/>
          <geometry>
              <mesh filename="package://deepmind_bot_description/meshes/gripper.dae" scale="${base_box_factor} ${base_box_factor} ${base_box_factor}"/>
          </geometry>
        </collision> -->

        <inertial>
          <mass value="0.005"/>
          <origin rpy="0 0 0" xyz="0 0 0.051"/>
          <inertia ixx="4.555416666666666e-06" ixy="0" ixz="0" iyy="5.130704166666666e-06" iyz="0" izz="1.0161208333333335e-06"/>
        </inertial>

      </link>

        <joint name="${robot_name}_gripper1_joint" type="revolute">
            <safety_controller k_position="1000.0" k_velocity="400.0" soft_lower_limit="-0.9" soft_upper_limit="0.9" />
            <origin rpy="3.1416 0 -1.57" xyz="-0.010128 -0.039741 -0.049894" />
            <parent link="${robot_name}_arm6" />
            <child link="${robot_name}_gripper1" />
            <axis xyz="0 1 0" />
            <limit effort="${arm_effort}" lower="-1.0" upper="1.0" velocity="2.3925" />
        </joint>


        <link name="${robot_name}_gripper2">
        <visual>
          <geometry>
              <mesh filename="package://deepmind_bot_description/meshes/gripper.dae" scale="${base_box_factor} ${base_box_factor} ${base_box_factor}"/>
          </geometry>
        </visual>

        <!-- <collision>
          <origin rpy="0 0 0" xyz="0 0 0"/>
          <geometry>
              <mesh filename="package://deepmind_bot_description/meshes/gripper.dae" scale="${base_box_factor} ${base_box_factor} ${base_box_factor}"/>
          </geometry>
        </collision> -->

        <inertial>
          <mass value="0.005"/>
          <origin rpy="0 0 0" xyz="0 0 0.051"/>
          <inertia ixx="4.555416666666666e-06" ixy="0" ixz="0" iyy="5.130704166666666e-06" iyz="0" izz="1.0161208333333335e-06"/>
        </inertial>

      </link>

        <joint name="${robot_name}_gripper2_joint" type="revolute">
            <safety_controller k_position="1000.0" k_velocity="400.0" soft_lower_limit="-0.9" soft_upper_limit="0.9" />
            <origin rpy="3.1416 0 1.57" xyz="0.010128 0.039741 -0.049894" />
            <parent link="${robot_name}_arm6" />
            <child link="${robot_name}_gripper2" />
            <axis xyz="0 1 0" />
            <limit effort="${arm_effort}" lower="-1.0" upper="1.0" velocity="2.3925" />
        </joint>
      

    </xacro:macro >

</robot>